<?xml version="1.0" encoding="utf-8" ?>
<!-- This URDF was automatically created by SolidWorks to URDF Exporter! Originally created by Stephen Brawner (brawner@gmail.com) 
     Commit Version: 1.6.0-1-g15f4949  Build Version: 1.6.7594.29634
     For more information, please see http://wiki.ros.org/sw_urdf_exporter -->
<robot name="adele_urdf_2">
    <link name="base_link">
        
<inertial>
            <origin xyz="0.14711 0.11636 0.020529" rpy="0 0 0" />
            <mass value="2.3915" />
            <inertia ixx="0.010502" ixy="-0.00010468" ixz="-1.3284E-05" iyy="0.014799" iyz="3.6894E-06" izz="0.025048" />
        </inertial>

        <visual>
            <origin xyz="0 0 0" rpy="0 0 0" />
            <geometry>
                <mesh filename="package://adele_urdf_2/meshes/base_link.STL" />
            </geometry>
            <material name="">
                <color rgba="0 0 0 1" />
            </material>
        </visual>
        <collision>
            <origin xyz="0 0 0" rpy="0 0 0" />
            <geometry>
                <mesh filename="package://adele_urdf_2/meshes/base_link.STL" />
            </geometry>
        </collision>
    </link>
    <link name="Link_1">
        
<inertial>
            <origin xyz="-0.0087894 -1.2827E-05 0.079289" rpy="0 0 0" />
            <mass value="1" />
            <inertia ixx="0.0019625" ixy="-1.6424E-07" ixz="-3.6449E-06" iyy="0.0018442" iyz="-6.9866E-07" izz="0.0019176" />
        </inertial>

        <visual>
            <origin xyz="0 0 0" rpy="0 0 0" />
            <geometry>
                <mesh filename="package://adele_urdf_2/meshes/Link_1.STL" />
            </geometry>
            <material name="">
                <color rgba="0.90588 0.63529 0 1" />
            </material>
        </visual>
        <collision>
            <origin xyz="0 0 0" rpy="0 0 0" />
            <geometry>
                <mesh filename="package://adele_urdf_2/meshes/Link_1.STL" />
            </geometry>
        </collision>
    </link>
    <joint name="Joint_1" type="revolute">
        <origin xyz="0.11903 0.085 0.052" rpy="0 0 0" />
        <parent link="base_link" />
        <child link="Link_1" />
        <axis xyz="0 0 1" />
        <limit lower="-2" upper="2" effort="0" velocity="125.7" />
        <safety_controller soft_upper="1.75" soft_lower="-1.75" k_velocity="0" />
    </joint>
    <link name="Link_2">
        
<inertial>
            <origin xyz="0.080396 0.0026836 0.14954" rpy="0 0 0" />
            <mass value="2" />
            <inertia ixx="0.0066083" ixy="-3.7186E-06" ixz="-1.4851E-05" iyy="0.0064738" iyz="-3.2275E-07" izz="0.0023282" />
        </inertial>

        <visual>
            <origin xyz="0 0 0" rpy="0 0 0" />
            <geometry>
                <mesh filename="package://adele_urdf_2/meshes/Link_2.STL" />
            </geometry>
            <material name="">
                <color rgba="0.96471 0.96471 0.95294 1" />
            </material>
        </visual>
        <collision>
            <origin xyz="0 0 0" rpy="0 0 0" />
            <geometry>
                <mesh filename="package://adele_urdf_2/meshes/Link_2.STL" />
            </geometry>
        </collision>
    </link>
    <joint name="Joint_2" type="revolute">
        <origin xyz="-0.037604 0.0012779 0.10236" rpy="0 0 0" />
        <parent link="Link_1" />
        <child link="Link_2" />
        <axis xyz="-1 0 0" />
        <limit lower="-1.57" upper="1.57" effort="0" velocity="125.7" />
    </joint>
    <link name="Link_3">
        
<inertial>
            <origin xyz="0.091739 -0.0051381 -0.14985" rpy="0 0 0" />
            <mass value="2" />
            <inertia ixx="0.0066027" ixy="3.7186E-06" ixz="1.4851E-05" iyy="0.0064636" iyz="-3.2275E-07" izz="0.0023227" />
        </inertial>

        <visual>
            <origin xyz="0 0 0" rpy="0 0 0" />
            <geometry>
                <mesh filename="package://adele_urdf_2/meshes/Link_3.STL" />
            </geometry>
            <material name="">
                <color rgba="0.96078 0.96078 0.96471 1" />
            </material>
        </visual>
        <collision>
            <origin xyz="0 0 0" rpy="0 0 0" />
            <geometry>
                <mesh filename="package://adele_urdf_2/meshes/Link_3.STL" />
            </geometry>
        </collision>
    </link>
    <joint name="Joint_3" type="revolute">
        <origin xyz="0.037604 0.047022 0.19894" rpy="-3.1416 0 -1.5708" />
        <parent link="Link_2" />
        <child link="Link_3" />
        <axis xyz="-1 0 0" />
        <limit lower="-1.57" upper="1.57" effort="0" velocity="125.7" />
    </joint>
    <link name="Link_4">
        
<inertial>
            <origin xyz="0.12304 -1.846E-06 0.078976" rpy="0 0 0" />
            <mass value="1.2" />
            <inertia ixx="0.0029198" ixy="2.5183E-08" ixz="3.294E-06" iyy="0.0024605" iyz="-2.1396E-07" izz="0.0007381" />
        </inertial>

        <visual>
            <origin xyz="0 0 0" rpy="0 0 0" />
            <geometry>
                <mesh filename="package://adele_urdf_2/meshes/Link_4.STL" />
            </geometry>
            <material name="">
                <color rgba="0.62745 0.62745 0.62745 1" />
            </material>
        </visual>
        <collision>
            <origin xyz="0 0 0" rpy="0 0 0" />
            <geometry>
                <mesh filename="package://adele_urdf_2/meshes/Link_4.STL" />
            </geometry>
        </collision>
    </link>
    <joint name="Joint_4" type="revolute">
        <origin xyz="0.0483 -0.0403 -0.2" rpy="3.1416 0 1.5708" />
        <parent link="Link_3" />
        <child link="Link_4" />
        <axis xyz="-1 0 0" />
        <limit lower="-1.57" upper="1.57" effort="0" velocity="125.7" />
    </joint>
    <link name="Link_5">
        
<inertial>
            <origin xyz="0.081501 -0.0075543 0.0028358" rpy="0 0 0" />
            <mass value="1" />
            <inertia ixx="0.0010332" ixy="9.7176E-07" ixz="-2.4621E-05" iyy="0.0011642" iyz="2.5598E-06" izz="0.0011663" />
        </inertial>

        <visual>
            <origin xyz="0 0 0" rpy="0 0 0" />
            <geometry>
                <mesh filename="package://adele_urdf_2/meshes/Link_5.STL" />
            </geometry>
            <material name="">
                <color rgba="0.90588 0.63529 0 1" />
            </material>
        </visual>
        <collision>
            <origin xyz="0 0 0" rpy="0 0 0" />
            <geometry>
                <mesh filename="package://adele_urdf_2/meshes/Link_5.STL" />
            </geometry>
        </collision>
    </link>
    <joint name="Joint_5" type="revolute">
        <origin xyz="0.1251 0 0.2" rpy="0 0 3.1416" />
        <parent link="Link_4" />
        <child link="Link_5" />
        <axis xyz="-1 0 0" />
        <limit lower="-1.57" upper="1.57" effort="0" velocity="125.7" />
    </joint>
    <link name="Link_6">
        
<inertial>
            <origin xyz="-0.0026064 2.0817E-17 -1.1102E-16" rpy="0 0 0" />
            <mass value="0.0036914" />
            <inertia ixx="5.7576E-07" ixy="-1.3579E-21" ixz="-6.4364E-21" iyy="2.9553E-07" iyz="2.5681E-23" izz="2.9553E-07" />
        </inertial>

        <visual>
            <origin xyz="0 0 0" rpy="0 0 0" />
            <geometry>
                <mesh filename="package://adele_urdf_2/meshes/Link_6.STL" />
            </geometry>
            <material name="">
                <color rgba="0.90588 0.63529 0 1" />
            </material>
        </visual>
        <collision>
            <origin xyz="0 0 0" rpy="0 0 0" />
            <geometry>
                <mesh filename="package://adele_urdf_2/meshes/Link_6.STL" />
            </geometry>
        </collision>
    </link>
    <joint name="Joint_6" type="revolute">
        <origin xyz="0.0848 0.0857 0" rpy="-3.1416 0 1.5708" />
        <parent link="Link_5" />
        <child link="Link_6" />
        <axis xyz="-1 0 0" />
        <limit lower="-0.785398" upper="0.785398" effort="0" velocity="125.7" />
    </joint>
    
<transmission name="trans_Joint_1">
        <type>transmission_interface/SimpleTransmission</type>
        <joint name="Joint_1">
            <hardwareInterface>hardware_interface/PositionJointInterface</hardwareInterface>
        </joint>
        <actuator name="Joint_1_motor">
            <hardwareInterface>hardware_interface/PositionActuatorInterface</hardwareInterface>
            <mechanicalReduction>6.5</mechanicalReduction>
        </actuator>
    </transmission>
    <transmission name="trans_Joint_2">
        <type>transmission_interface/SimpleTransmission</type>
        <joint name="Joint_2">
            <hardwareInterface>hardware_interface/PositionJointInterface</hardwareInterface>
        </joint>
        <actuator name="Joint_2_motor">
            <hardwareInterface>hardware_interface/PositionActuatorInterface</hardwareInterface>
            <mechanicalReduction>-20</mechanicalReduction>
        </actuator>
    </transmission>
    <transmission name="trans_Joint_3">
        <type>transmission_interface/SimpleTransmission</type>
        <joint name="Joint_3">
            <hardwareInterface>hardware_interface/PositionJointInterface</hardwareInterface>
        </joint>
        <actuator name="Joint_3_motor">
            <hardwareInterface>hardware_interface/PositionActuatorInterface</hardwareInterface>
            <mechanicalReduction>-20</mechanicalReduction>
        </actuator>
    </transmission>
    <transmission name="trans_Joint_4">
        <type>transmission_interface/SimpleTransmission</type>
        <joint name="Joint_4">
            <hardwareInterface>hardware_interface/PositionJointInterface</hardwareInterface>
        </joint>
        <actuator name="Joint_4_motor">
            <hardwareInterface>hardware_interface/PositionActuatorInterface</hardwareInterface>
            <mechanicalReduction>-20</mechanicalReduction>
        </actuator>
    </transmission>
    <transmission name="trans_Joint_5">
        <type>transmission_interface/SimpleTransmission</type>
        <joint name="Joint_5">
            <hardwareInterface>hardware_interface/PositionJointInterface</hardwareInterface>
        </joint>
        <actuator name="Joint_5_motor">
            <hardwareInterface>hardware_interface/PositionActuatorInterface</hardwareInterface>
            <mechanicalReduction>1</mechanicalReduction>
        </actuator>
    </transmission>
    <transmission name="trans_Joint_6">
        <type>transmission_interface/SimpleTransmission</type>
        <joint name="Joint_6">
            <hardwareInterface>hardware_interface/PositionActuatorInterface</hardwareInterface>
        </joint>
        <actuator name="Joint_6_motor">
            <hardwareInterface>hardware_interface/EffortJointInterface</hardwareInterface>
            <mechanicalReduction>1</mechanicalReduction>
        </actuator>
    </transmission>
    <gazebo>
        <plugin name="gazebo_ros_control" filename="libgazebo_ros_control.so">
            <robotNamespace>/AdeleHW</robotNamespace>
        </plugin>
    </gazebo>
</robot>
